<?xml version = "1.0"?>
<robot name="gripper">
<!-- the orange axis is x axis, yellow is y and cyan is z axis -->
    <material name="body_color">
        <color rgba="0.3451 0.3451 0.3451 1.0"/>
    </material>
    <material name="finger_color">
        <color rgba="0.0 0.0 0.0 1.0"/>
    </material>
    <material name="finger_base_color">
        <color rgba="0.2 0.05098039 0.21960784 1.0"/>
    </material>
    <link name="gripper_base_link">
        <visual>
            <geometry>
                <cylinder radius="0.039" length="0.006"/>
            </geometry>    
            <origin rpy = "0 0 0 " xyz="0 0 0.003"/>
            <material name="body_color"/>
        </visual>
        <collision>
            <geometry>
                <cylinder radius="0.039" length="0.006"/>
            </geometry>    
            <origin rpy = "0 0 0 " xyz="0 0 0"/>
        </collision>    
        <inertial>
            <origin xyz="0.0 0.0 0.0" rpy="0.0 0.0 0.0"/>
            <mass value="0.0"/>
            <inertia ixx=" 1.533e-05 " ixy=" 0.0 " ixz=" 0.0 " iyy=" 1.533e-05 " iyz=" 0.0 " izz=" 3.042e-05 "/>
        </inertial>
    </link>

    <joint name="gripper_base" type="fixed">
        <parent link="gripper_base_link"/>
        <child link="gripper_first_link"/>
        <origin xyz="0 0 0.006"/>
        <axis xyz="0 0 0"/>
        <limit lower="-1.2" upper="1.2" effort="300" velocity="2.0"/>
    </joint>

    <link name="gripper_first_link">
        <visual>
            <geometry>
                <box size="0.08 0.06 0.063"/>
            </geometry>
            <origin rpy="0 0 0" xyz="0 0 0.0315"/>
            <material name="body_color"/>
        </visual>
        <collision>
            <geometry>
                <box size="0.08 0.06 0.069"/>
            </geometry>
            <origin rpy="0 0 0" xyz="0 0 0.0345"/>
        </collision>
        <inertial>
            <origin xyz="0.0 0.0 0.0" rpy="0.0 0.0 0.0"/>
            <mass value="0.0"/>
            <inertia ixx=" 0.0002765066666666667 " ixy=" 0.0 " ixz=" 0.0 " iyy=" 0.00020184 " iyz=" 0.0 " izz=" 0.0002666666666666667 "/>
        </inertial>
    </link>

    <joint name="right_finger_base_joint" type="prismatic">
        <parent link="gripper_first_link"/>
        <child link="right_finger_base"/>
        <origin xyz="0 0 0.063"/>
        <axis xyz="1 0 0"/>
        <limit lower="0.0" upper="0.03" effort="300" velocity="2.0"/>
    </joint>

    <joint name="left_finger_base_joint" type="prismatic">
        <mimic joint="right_finger_base_joint" multiplier="1" offset="0"/>
        <parent link="gripper_first_link"/>
        <child link="left_finger_base"/>
        <origin xyz="0.0 0.0 0.063"/>
        <axis xyz="-1 0 0"/>
        <limit lower="0.0" upper="0.03" effort="300" velocity="2.0"/>
    </joint>

    <link name="right_finger_base">
        <visual>
            <geometry>
                <box size="0.025 0.005 0.008"/>
            </geometry>
            <origin rpy="0 0 0" xyz="-0.0125 0.0025 0.004"/>
            <material name="finger_base_color"/>
            <!-- <material>
                <color rgba="0.0 1.0 0.0 1.0"/>                
            </material> -->
        </visual>
        <collision>
            <geometry>
                <box size="0.025 0.005 0.008"/>
            </geometry>
            <origin rpy="0 0 0" xyz="-0.0125 0.0025 0.004"/>           
        </collision>
        <inertial>
            <origin xyz="0.0 0.0 0.0" rpy="0.0 0.0 0.0"/>
            <mass value="0.0"/>
            <inertia ixx=" 2.870833333333334e-07 " ixy=" 0.0 " ixz=" 0.0 " iyy=" 3.708333333333333e-08 " iyz=" 0.0 " izz=" 2.7083333333333337e-07 "/>
        </inertial>
    </link>

    <link name="left_finger_base">
        <visual>
            <geometry>
                <box size="0.025 0.005 0.008"/>
            </geometry>
            <origin rpy="0 0 0" xyz="0.0125 -0.0025 0.004"/>
            <material name="finger_base_color"/>
            <!-- <material>
                <color rgba="1.0 0.0 0.0 1.0"/>                
            </material> -->
        </visual>
        <collision>
            <geometry>
                <box size="0.025 0.005  0.008"/>
            </geometry>
            <origin rpy="0 0 0" xyz="0.0125 -0.0025 0.004"/>      
        </collision>
        <inertial>
            <origin xyz="0.0 0.0 0.0" rpy="0.0 0.0 0.0"/>
            <mass value="0.0"/>
            <inertia ixx=" 2.870833333333334e-07 " ixy=" 0.0 " ixz=" 0.0 " iyy=" 3.708333333333333e-08 " iyz=" 0.0 " izz=" 2.7083333333333337e-07 "/>
        </inertial>
    </link>
    <!-- might need to modify the axis of translation -->
    <joint name="right_finger_joint" type="fixed">
        <parent link="right_finger_base"/>
        <child link="right_finger"/>
        <origin rpy="0 0 0" xyz="0 0 0.008"/>
        <axis xyz="0 0 0"/>
        <!-- <limit lower="0.0" upper="0.03" effort="300" velocity="2.0"/> -->
    </joint>

    <joint name="left_finger_joint" type="fixed">
        <parent link="left_finger_base"/>
        <child link="left_finger"/>
        <origin rpy="0 0 0" xyz="0 0 0.008"/>
        <axis xyz="0 0 0"/>
        <!-- <limit lower="0.0" upper="0.03" effort="300" velocity="2.0"/> -->
    </joint>

    <link name="right_finger">
        <visual>
            <geometry>
                <box size="0.01 0.01 0.034"/>  
            </geometry>
            <origin rpy="0 0 0" xyz="0.005 0 0.0170"/>  
            <!-- <material name="finger_color"/>  -->
            <material>
                <color rgba="0.2 0.2 0.2 1.0"/>
            </material>
        </visual>
        <collision>
            <geometry>
                <box size="0.01 0.01 0.034"/>  
            </geometry>
            <origin rpy="0 0 0" xyz="0.005 0 0.0170"/>            
        </collision>
        <inertial>
            <origin xyz="0.0 0.0 0.0" rpy="0.0 0.0 0.0"/>
            <mass value="0.0"/>
            <inertia ixx=" 1.5700000000000002e-06 " ixy=" 0.0 " ixz=" 0.0 " iyy=" 1.5700000000000002e-06 " iyz=" 0.0 " izz=" 2.5e-07 "/>
        </inertial>
    </link>

    <link name="left_finger">
        <visual>
            <geometry>
                <box size="0.01 0.01 0.034"/>  
            </geometry>
            <origin rpy="0 0 0" xyz="-0.005  0 0.0170"/>
            <material name="finger_color"/> 
        </visual>
        <collision>
            <geometry>
                <box size="0.01 0.01 0.034"/>  
            </geometry>
            <origin rpy="0 0 0" xyz="-0.005  0 0.0170"/>           
        </collision>
        <inertial>
            <origin xyz="0.0 0.0 0.0" rpy="0.0 0.0 0.0"/>
            <mass value="0.0"/>
            <inertia ixx=" 1.5700000000000002e-06 " ixy=" 0.0 " ixz=" 0.0 " iyy=" 1.5700000000000002e-06 " iyz=" 0.0 " izz=" 2.5e-07 "/>
        </inertial>
    </link>

</robot>